<?xml version="1.0" encoding="utf-8"?>

<robot name="arm_upper" xmlns:xacro="http://ros.org/wiki/xacro">

  <!-- Define a number of dimensions using properties -->
  <xacro:property name="arm_upper_offset_x" value="0.06" />
  <xacro:property name="arm_upper_offset_y" value="0" />
  <xacro:property name="arm_upper_offset_z" value="0.1" />
  <xacro:property name="arm_upper_radius" value="0.009" />
  <!-- <xacro:property name="arm_upper_length" value="0.32" />  -->
  <xacro:property name="arm_upper_length" value="0.32" /> 


     
  <!-- Define the torso -->
  <xacro:macro name="arm_upper" params="parent name">
    <joint name="shoulder_joint" type="revolute">
      <origin xyz="${arm_upper_offset_x} ${arm_upper_offset_y} ${arm_upper_offset_z}" rpy="0 0 0" />
      <axis xyz="0 1 0"/>
      <limit effort="1.0" lower="${-M_PI}" upper="0" velocity="1.571"/>
      <parent link="${parent}_link"/>
      <child link="${name}_link"/>
    </joint>
    <link name="${name}_link">
      <inertial>
        <mass value="0.5" />
        <origin xyz="0 0 0" />
        <inertia ixx="1.0" ixy="0.0" ixz="0.0"
                 iyy="1.0" iyz="0.0"
                 izz="1.0" />
      </inertial>

      <visual>
        <origin xyz="-0.01 0 -0.39" rpy="0 ${87.5*M_PI/180} 0" />
	<geometry>
	  <mesh filename="package://hard_description/meshes/mini/arm_simple_mini.dae" scale="${mesh_scale} ${mesh_scale} ${mesh_scale} " />
	</geometry>
	<!-- <material color="yellow"/> -->
      </visual>
      <collision>
        <origin xyz="0 0 -0.24" rpy="0 0 0" />
        <geometry>
	  <cylinder length="${arm_upper_length}" radius="${arm_upper_radius}" />
        </geometry>
      </collision>  
    </link>
  </xacro:macro>

</robot>
