<?xml version="1.0" encoding="utf-8"?>

<robot name="wrist_pitch" xmlns:xacro="http://ros.org/wiki/xacro">

  <!-- Define a number of dimensions using properties -->
  <xacro:property name="wrist_offset_x" value="0" />
  <xacro:property name="wrist_offset_y" value="0" />
  <xacro:property name="wrist_offset_z" value="-0.343" />
  <xacro:property name="wrist_radius" value="0.025" />
  <xacro:property name="wrist_length" value="0.1" />
     
  <!-- Define the torso -->
  <xacro:macro name="wrist_pitch" params="parent name">
    <joint name="${name}_joint" type="revolute">
      <origin xyz="${wrist_offset_x} ${wrist_offset_y} ${wrist_offset_z}" rpy="0 0 0" />
      <axis xyz="0 1 0"/>
      <limit effort="1.0" lower="-2.617" upper="2.617" velocity="1.571"/>
      <parent link="${parent}_link"/>
      <child link="${name}_link"/>
    </joint>
    <link name="${name}_link">
      <inertial>
        <mass value="0.1" />
        <origin xyz="0 0 0" />
        <inertia ixx="1.0" ixy="0.0" ixz="0.0"
                 iyy="1.0" iyz="0.0"
                 izz="1.0" />
      </inertial>
      <visual>
        <origin xyz="-0.011 0.0 -0.044" rpy="0 ${M_PI/2} 0" />
	<geometry>
	  <!-- New big arm -->
          <!-- <mesh filename="package://hard_description/meshes/arm_upper_mini.dae" scale="${mesh_scale} ${mesh_scale} ${mesh_scale}" /> -->
	  <!-- Old but a simple arm -->
	  <mesh filename="package://hard_description/meshes/mini/wrist_simple_mini.dae" scale="${mesh_scale} ${mesh_scale} ${mesh_scale}" />
	</geometry>
	<!-- <material color="yellow"/> -->
      </visual>
      <!-- <collision>
      <origin xyz="0.14 -0.16 0.5" rpy="${M_PI/100} 0 0" />
      <geometry>
          <cylinder length="${wrist_length}" radius="${wrist_radius}" />
      </geometry>
    </collision> -->
    </link>
  </xacro:macro>

</robot>
